{
    "problem_identifier": "problem_20",
    "prompt_identifier": "prompt_1",
    "model_identifier": "gpt-4",
    "score": 0.0,
    "sub_criteria_scores": null,
    "issues": [
        "Error encountered during execution for test case Input: contour1 = [[0, 0], [1, 0], [1, 1], [0, 1]], contour2 = [[1, 1], [2, 1], [2, 2], [1, 2]]; Expected Output: 0.0: shapes (4,2) and (4,) not aligned: 2 (dim 1) != 4 (dim 0)\nTraceback (most recent call last):\n  File \"/data/Lining/Lining/HW/LLMCodingBenchmarkingFramework-main/execution.py\", line 76, in executor_script\n    result = function(*parameters)\n  File \"<string>\", line 27, in principal_axis_alignment_comparison\n  File \"<string>\", line 22, in alignment_distance\nValueError: shapes (4,2) and (4,) not aligned: 2 (dim 1) != 4 (dim 0)\n",
        "Error encountered during execution for test case Input: contour1 = [[1, 1], [2, 1], [2, 2], [1, 2]], contour2 = [[2, 2], [3, 2], [3, 3], [2, 3]]; Expected Output: 0.0: shapes (4,2) and (4,) not aligned: 2 (dim 1) != 4 (dim 0)\nTraceback (most recent call last):\n  File \"/data/Lining/Lining/HW/LLMCodingBenchmarkingFramework-main/execution.py\", line 76, in executor_script\n    result = function(*parameters)\n  File \"<string>\", line 27, in principal_axis_alignment_comparison\n  File \"<string>\", line 22, in alignment_distance\nValueError: shapes (4,2) and (4,) not aligned: 2 (dim 1) != 4 (dim 0)\n"
    ]
}